<?xml version="1.0" ?>
<robot name="mini_cheetah_vision" xmlns:xacro="http://ros.org/wiki/xacro">
    <material name="black">
      <color rgba="0.0 0.0 0.0 1.0"/>
    </material>
    <material name="blue">
      <color rgba="0.0 0.0 0.8 1.0"/>
    </material>
    <material name="green">
      <color rgba="0.0 0.8 0.0 1.0"/>
    </material>
    <material name="grey">
      <color rgba="0.2 0.2 0.2 1.0"/>
    </material>
    <material name="silver">
      <color rgba="0.913725490196 0.913725490196 0.847058823529 1.0"/>
    </material>
    <material name="orange">
      <!-- <color rgba="1.0 0.423529411765 0.0392156862745 1.0"/> -->
      <color rgba="0.12 0.15 0.2 1.0"/>
    </material>
    <material name="brown">
      <color rgba="0.870588235294 0.811764705882 0.764705882353 1.0"/>
    </material>
    <material name="red">
      <color rgba="0.8 0.0 0.0 1.0"/>
    </material>
    <material name="white">
      <color rgba="1.0 1.0 1.0 1.0"/>
    </material>
    <link name="base">
      <visual>
        <origin rpy="0 0 0" xyz="0 0 0"/>
        <geometry>
          <box size="0.001 0.001 0.001"/>
        </geometry>
      </visual>
    </link>
    <joint name="floating_base" type="fixed">
      <origin rpy="0 0 0" xyz="0 0 0"/>
      <parent link="base"/>
      <child link="trunk"/>
    </joint>
    <link name="trunk">
        <inertial>
            <!-- <mass value="3.3"/> -->
            <mass value="2.65"/>
            <origin xyz="0.0 0.0 0.0"/>
            <inertia ixx="0.011253" ixy="0" ixz="0" iyy="0.362030" iyz="0" izz="0.042673"/>
        </inertial>
        <visual>
          <origin rpy="0.0 0.0 0.0" xyz="0.0 0.0 0.0"/>
          <geometry>
              <mesh filename="../meshes/mini_vision_body.dae" scale="1 1 1"/>
          </geometry>
          <material name="orange"/>
        </visual>
        <collision>
          <origin rpy="0 0 0" xyz="0 0 0.0"/>
          <geometry>
            <mesh filename="../meshes/mini_vision_body.dae" scale="1 1 1"/>
          </geometry>
        </collision>
    </link>

     <joint name="FR_hip_joint" type="revolute">
        <axis xyz="1 0 0"/>
        <origin rpy="0 0 0" xyz="0.14775 -0.049 0.0"/>
        <parent link="trunk"/>
        <child link="FR_hip"/>
        <dynamics damping="0.0" friction="0.0"/>
        <limit effort="17" lower="-0.8" upper="0.8" velocity="40"/>
    </joint>
    <link name="FR_hip">
        <inertial>
            <mass value="0.54"/>
            <origin xyz="0.055 -0.036 0."/>
            <inertia ixx="0.000381" ixy="0.000058" ixz="0.00000045"
                iyy="0.000560" iyz="0.00000095" izz="0.000444"/>
        </inertial>
        <visual>
            <geometry>
                <mesh filename="../meshes/mini_vision_abd.dae"/>
            </geometry>
            <origin rpy="0.0 0.0 0.0" xyz="0.0 0.0 0.0"/>
        </visual>
        <!-- <collision>
            <geometry>
                <mesh filename="../meshes/mini_vision_abd.obj"/>
            </geometry>
            <origin rpy="0. 0. 0." xyz="0. 0 0"/>
        </collision> -->
    </link>
    <joint name="FR_thigh_joint" type="revolute">
        <axis xyz="0 -1 0"/>
        <origin rpy="0.0 0.0 0.0" xyz="0.055 -0.019 0.00"/>
        <parent link="FR_hip"/>
        <child link="FR_thigh"/>
        <dynamics damping="0.0" friction="0.0"/>
        <limit effort="17" lower="-2.5" upper="1.0" velocity="40"/>
    </joint>
    <link name="FR_thigh">
        <inertial>
            <mass value="0.634"/>
            <origin xyz="0.0 0.016 -0.02"/>
            <inertia ixx="0.001983" ixy="0.000245" ixz="0.000013"
                iyy="0.002103" iyz="0.0000015" izz="0.000408"/>
        </inertial>
        <visual>
            <geometry>
                <mesh filename="../meshes/mini_vision_shank.dae"/>
            </geometry>
            <origin rpy="0.0 0.0 0.0" xyz="0.0 0.0 0.0"/>
        </visual>
        <collision>
          <origin rpy="0 1.57079632679 0" xyz="0 -0.05 -0.1"/>
          <geometry>
            <box size="0.2585 0.034 0.043"/>
          </geometry>
        </collision>
    </link>

    <joint name="FR_calf_joint" type="revolute">
        <axis xyz="0 -1 0"/>
        <origin rpy="0.0 0 0.0" xyz="0.0 -0.049 -0.2085"/>
        <parent link="FR_thigh"/>
        <child link="FR_calf"/>
        <dynamics damping="0.0" friction="0.0"/>
        <limit effort="17" lower="1.0" upper="2.5" velocity="40"/>
    </joint>
    <link name="FR_calf">
        <inertial>
            <mass value="0.064"/>
            <origin xyz="0.0 0.0 -0.061"/>
            <inertia ixx="0.000245" ixy="0" ixz="0.0" iyy="0.000248" iyz="0" izz="0.000006"/>
        </inertial>
        <visual>
            <geometry>
                <mesh filename="../meshes/lower_leg.dae"/>
            </geometry>
            <origin rpy="0.0 0.0 0.0" xyz="0.0 0.0 0.0"/>
        </visual>
        <collision>
          <origin rpy="0 0 0" xyz="0 0 -0.09"/>
          <geometry>
            <box size="0.025 0.025 0.1955"/>
          </geometry>
        </collision>
    </link>
    <joint name="FR_foot_fixed" type="fixed" dont_collapse="true">
      <origin rpy="0 0 0" xyz="0 -0.004 -0.195"/>
      <parent link="FR_calf"/>
      <child link="FR_foot"/>
    </joint>
    <!-- this link is only for collision -->
    <link name="FR_foot">
      <visual>
        <origin rpy="0 0 0" xyz="0 0 0"/>
        <geometry>
          <sphere radius="0.01"/>
        </geometry>
        <material name="orange"/>
      </visual>
      <collision>
        <origin rpy="0.0 0.0 0" xyz="0 0.0 0"/>
        <geometry>
          <sphere radius="0.0185"/>
        </geometry>
      </collision>
      <inertial>
        <mass value="0.06"/>
        <inertia ixx="9.6e-06" ixy="0.0" ixz="0.0" iyy="9.6e-06" iyz="0.0" izz="9.6e-06"/>
      </inertial>
    </link>

    <joint name="FL_hip_joint" type="revolute">
        <axis xyz="1 0 0"/>
        <origin rpy="0 0 0" xyz="0.14775 0.049 0.0"/>
        <parent link="trunk"/>
        <child link="FL_hip"/>
        <dynamics damping="0.0" friction="0.0"/>
        <limit effort="17" lower="-0.8" upper="0.8" velocity="40"/>
    </joint>
    <link name="FL_hip">
        <inertial>
            <mass value="0.54"/>
            <origin xyz="0.055 0.036 0."/>
            <inertia ixx="0.000381" ixy="0.000058" ixz="0.00000045"
                iyy="0.000560" iyz="0.00000095" izz="0.000444"/>
        </inertial>
        <visual>
            <geometry>
                <mesh filename="../meshes/mini_vision_abd.dae"/>
            </geometry>
            <origin rpy="3.141592 0.0 0.0" xyz="0.0 0.0 0.0"/>
        </visual>

    </link>

    <joint name="FL_thigh_joint" type="revolute">
        <axis xyz="0 -1 0"/>
        <origin rpy="0.0 0.0 0.0" xyz="0.055 0.019 0.00"/>
        <parent link="FL_hip"/>
        <child link="FL_thigh"/>
        <dynamics damping="0.0" friction="0.0"/>
        <limit effort="17" lower="-2.5" upper="1.0" velocity="40"/>
    </joint>
    <link name="FL_thigh">
        <inertial>
            <mass value="0.634"/>
            <origin xyz="0.0 0.016 -0.02"/>
            <inertia ixx="0.001983" ixy="0.000245" ixz="0.000013"
                iyy="0.002103" iyz="0.0000015" izz="0.000408"/>
        </inertial>
        <visual>
            <geometry>
                <mesh filename="../meshes/mini_vision_shank.dae"/>
            </geometry>
            <origin rpy="0.0 0 3.141592" xyz="0.0 0.0 0.0"/>
        </visual>
        <collision>
          <origin rpy="0 1.57079632679 0" xyz="0 0.05 -0.1"/>
          <geometry>
            <box size="0.2585 0.034 0.043"/>
          </geometry>
        </collision>
    </link>

    <joint name="FL_calf_joint" type="revolute">
        <axis xyz="0 -1 0"/>
        <origin rpy="0.0 0 0.0" xyz="0.0 0.049 -0.2085"/>
        <parent link="FL_thigh"/>
        <child link="FL_calf"/>
        <dynamics damping="0.0" friction="0.0"/>
        <limit effort="17" lower="1.0" upper="2.5" velocity="40"/>
    </joint>
    <link name="FL_calf">
        <inertial>
            <mass value="0.064"/>
            <origin xyz="0.0 0.0 -0.061"/>
            <inertia ixx="0.000245" ixy="0" ixz="0.0" iyy="0.000248" iyz="0" izz="0.000006"/>
        </inertial>
        <visual>
            <geometry>
                <mesh filename="../meshes/lower_leg.dae"/>
            </geometry>
            <origin rpy="0.0 0.0 3.141592" xyz="0.0 0.0 0.0"/>
        </visual>

        <collision>
          <origin rpy="0 0 0" xyz="0 0 -0.09"/>
          <geometry>
            <box size="0.025 0.025 0.1955"/>
          </geometry>
        </collision>
    </link>
    <joint name="FL_foot_fixed" type="fixed" dont_collapse="true">
      <origin rpy="0 0 0" xyz="0 0.004 -0.195"/>
      <parent link="FL_calf"/>
      <child link="FL_foot"/>
    </joint>
    <!-- this link is only for collision -->
    <link name="FL_foot">
      <collision>
        <origin rpy="0.0 0.0 0" xyz="0 0.0 0"/>
        <geometry>
          <sphere radius="0.0185"/>
        </geometry>
      </collision>
      <inertial>
        <mass value="0.06"/>
        <inertia ixx="9.6e-06" ixy="0.0" ixz="0.0" iyy="9.6e-06" iyz="0.0" izz="9.6e-06"/>
      </inertial>
    </link>

    <joint name="RR_hip_joint" type="revolute">
        <axis xyz="-1 0 0"/>
        <origin rpy="0 3.141592 0" xyz="-0.14775 -0.049 0.0"/>
        <parent link="trunk"/>
        <child link="RR_hip"/>
        <dynamics damping="0.0" friction="0.0"/>
        <limit effort="17" lower="-0.8" upper="0.8" velocity="40"/>
    </joint>
    <link name="RR_hip">
        <inertial>
            <mass value="0.54"/>
            <origin xyz="0.055 -0.036 0."/>
            <inertia ixx="0.000381" ixy="0.000058" ixz="0.00000045"
                iyy="0.000560" iyz="0.00000095" izz="0.000444"/>
        </inertial>
        <visual>
            <geometry>
                <mesh filename="../meshes/mini_vision_abd.dae"/>
            </geometry>
            <origin rpy="0.0 0.0 0.0" xyz="0.0 0.0 0.0"/>
        </visual>
    </link>

    <joint name="RR_thigh_joint" type="revolute">
        <axis xyz="0 -1 0"/>
        <origin rpy="0.0 3.141592 0.0" xyz="0.055 -0.019 0.00"/>
        <parent link="RR_hip"/>
        <child link="RR_thigh"/>
        <dynamics damping="0.0" friction="0.0"/>
        <limit effort="17" lower="-2.5" upper="1.0" velocity="40"/>
    </joint>
    <link name="RR_thigh">
        <inertial>
            <mass value="0.634"/>
            <origin xyz="0.0 0.016 -0.02"/>
            <inertia ixx="0.001983" ixy="0.000245" ixz="0.000013"
                iyy="0.002103" iyz="0.0000015" izz="0.000408"/>
        </inertial>
        <visual>
            <geometry>
                <mesh filename="../meshes/mini_vision_shank.dae"/>
            </geometry>
            <origin rpy="0.0 0.0 0.0" xyz="0.0 0.0 0.0"/>
        </visual>
        <collision>
          <origin rpy="0 1.57079632679 0" xyz="0 -0.05 -0.1"/>
          <geometry>
            <box size="0.2585 0.034 0.043"/>
          </geometry>
        </collision>
    </link>

    <joint name="RR_calf_joint" type="revolute">
        <axis xyz="0 -1 0"/>
        <origin rpy="0.0 0 0.0" xyz="0.0 -0.049 -0.2085"/>
        <parent link="RR_thigh"/>
        <child link="RR_calf"/>
        <dynamics damping="0.0" friction="0.0"/>
        <limit effort="17"  lower="1.0" upper="2.5" velocity="40"/>
    </joint>
    <link name="RR_calf">
        <inertial>
            <mass value="0.064"/>
            <origin xyz="0.0 0.0 -0.061"/>
            <inertia ixx="0.000245" ixy="0" ixz="0.0" iyy="0.000248" iyz="0" izz="0.000006"/>
        </inertial>
        <visual>
            <geometry>
                <mesh filename="../meshes/lower_leg.dae"/>
            </geometry>
            <origin rpy="0.0 0.0 0.0" xyz="0.0 0.0 0.0"/>
        </visual>
        <collision>
          <origin rpy="0 0 0" xyz="0 0 -0.09"/>
          <geometry>
            <box size="0.025 0.025 0.1955"/>
          </geometry>
        </collision>
    </link>
    <joint name="RR_foot_fixed" type="fixed" dont_collapse="true">
      <origin rpy="0 0 0" xyz="0 -0.004 -0.195"/>
      <parent link="RR_calf"/>
      <child link="RR_foot"/>
    </joint>
    <!-- this link is only for collision -->
    <link name="RR_foot">
      <collision>
        <origin rpy="0.0 0.0 0" xyz="0 0.0 0"/>
        <geometry>
          <sphere radius="0.0185"/>
        </geometry>
      </collision>
      <inertial>
        <mass value="0.06"/>
        <inertia ixx="9.6e-06" ixy="0.0" ixz="0.0" iyy="9.6e-06" iyz="0.0" izz="9.6e-06"/>
      </inertial>
    </link>

    <joint name="RL_hip_joint" type="revolute">
        <axis xyz="-1 0 0"/>
        <origin rpy="0 3.141592 0" xyz="-0.14775 0.049 0.0"/>
        <parent link="trunk"/>
        <child link="RL_hip"/>
        <dynamics damping="0.0" friction="0.0"/>
        <limit effort="17" lower="-0.8" upper="0.8" velocity="40"/>
    </joint>
    <link name="RL_hip">
        <inertial>
            <mass value="0.54"/>
            <origin xyz="0.055 0.036 0."/>
            <inertia ixx="0.000381" ixy="0.000058" ixz="0.00000045"
                iyy="0.000560" iyz="0.00000095" izz="0.000444"/>
        </inertial>
        <visual>
            <geometry>
                <mesh filename="../meshes/mini_vision_abd.dae"/>
            </geometry>
            <origin rpy="3.141592 0.0 0.0" xyz="0.0 0.0 0.0"/>
        </visual>
    </link>

    <joint name="RL_thigh_joint" type="revolute">
        <axis xyz="0 -1 0"/>
        <origin rpy="0.0 3.141592 0.0" xyz="0.055 0.019 0.00"/>
        <parent link="RL_hip"/>
        <child link="RL_thigh"/>
        <dynamics damping="0.0" friction="0.0"/>
        <limit effort="17" lower="-2.5" upper="1.0" velocity="40"/>
    </joint>
    <link name="RL_thigh">
        <inertial>
            <mass value="0.634"/>
            <origin xyz="0.0 0.016 -0.02"/>
            <inertia ixx="0.001983" ixy="0.000245" ixz="0.000013"
                iyy="0.002103" iyz="0.0000015" izz="0.000408"/>
        </inertial>
        <visual>
            <geometry>
                <mesh filename="../meshes/mini_vision_shank.dae"/>
            </geometry>
            <origin rpy="0.0 0 3.141592" xyz="0.0 0.0 0.0"/>
        </visual>
        <collision>
          <origin rpy="0 1.57079632679 0" xyz="0.0 0.05 -0.1"/>
          <geometry>
            <box size="0.2585 0.034 0.043"/>
          </geometry>
        </collision>
    </link>

    <joint name="RL_calf_joint" type="revolute">
        <axis xyz="0 -1 0"/>
        <origin rpy="0.0 0 0.0" xyz="0.0 0.049 -0.2085"/>
        <parent link="RL_thigh"/>
        <child link="RL_calf"/>
        <dynamics damping="0.0" friction="0.0"/>
        <limit effort="17" lower="1.0" upper="2.5" velocity="40"/>
    </joint>
    <link name="RL_calf">
        <inertial>
            <mass value="0.064"/>
            <origin xyz="0.0 0.0 -0.061"/>
            <inertia ixx="0.000245" ixy="0" ixz="0.0" iyy="0.000248" iyz="0" izz="0.000006"/>
        </inertial>
        <visual>
            <geometry>
                <mesh filename="../meshes/lower_leg.dae"/>
            </geometry>
            <origin rpy="0.0 0.0 3.141592" xyz="0.0 0.0 0.0"/>
        </visual>
        <collision>
          <origin rpy="0 0 0" xyz="0 0 -0.09"/>
          <geometry>
            <box size="0.025 0.025 0.1955"/>
          </geometry>
        </collision>
    </link>
    <joint name="RL_foot_fixed" type="fixed" dont_collapse="true">
      <origin rpy="0 0 0" xyz="0 0.004 -0.195"/>
      <parent link="RL_calf"/>
      <child link="RL_foot"/>
    </joint>
    <!-- this link is only for collision -->
    <link name="RL_foot">
      <collision>
        <origin rpy="0.0 0.0 0" xyz="0 0 0"/>
        <geometry>
          <sphere radius="0.0185"/>
        </geometry>
      </collision>
      <inertial>
        <mass value="0.06"/>
        <inertia ixx="9.6e-06" ixy="0.0" ixz="0.0" iyy="9.6e-06" iyz="0.0" izz="9.6e-06"/>
      </inertial>
    </link>
</robot>
